Workbook

Sheet PARAM
B2: 1101164MYS.140005.BG0002

Sheet MASTER_BLOK
A1: Nama Blok | B1: Kod Blok | C1: Nama Fungsi Binaan | D1: Kod Fungsi Binaan
A2: Guiding Gallery 1 (Information Centre) - P7 | B2: B | C2: Bangunan Komersial | D2: BB0010
A3: Guiding Gallery 2 (Cafe) - P7 | B3: C | C3: Restoran | D3: BB0100
A4: Guiding Gallery 3 (Viewing Deck) - P7 | B4: D | C4: Bangunan Komersial | D4: BB0010
A5: Guiding Light Cafe - 3A3B | B5: E | C5: Restoran | D5: BB0100
A6: Promenade Cafe - 3A3B | B6: F | C6: Restoran | D6: BB0100
A7: Selera Medan Bunus - 1C1D | B7: G | C7: Restoran | D7: BB0100
A8: Cafe Jalan Tun Perak - 1C1D | B8: H | C8: Restoran | D8: BB0100
A9: Kiosk 1 Pocket Park - 1C1D | B9: I | C9: Restoran | D9: BB0100
A10: Kiosk 2 Pocket Park - 1C1D | B10: J | C10: Restoran | D10: BB0100
A11: Old Train Station Guiding Gallery - 4A4B | B11: K | C11: Bangunan Komersial | D11: BB0010
A12: Bike Repair Kiosk - 4A4B | B12: L | C12: Bangunan Komersial | D12: BB0010
... A16: Utility Room / Pump House - 1C1D | B16: P | C16: Pump House | D16: UC0080

Sheet MASTER_BINAAN_LUAR
A1: Nama Binaan Luar | B1: Kod Binaan Luar
A2: Cottage/ Wakaf | B2: BG0092
A3: Landscape | B3: BG0410
A4: Bus Stop/ Taxi Stop | B4: BJ0021
A5: Fencing | B5: BJ0400
A6: Walkway/Pedestrian/Footpath | B6: TA0112
A7: Overhead Crossing | B7: TA0140
A8: Pump House | B8: UC0080

Sheet MASTER_KOMPONEN
A1: Nama Komponen | B1: ID Komponen | C1: Bidang | D1: Sistem | E1: Subsistem | F1: Jenis | G1: Kategori Komponen
A2: CONFLUENCE GUIDING BRIDGE | B2: 1 | C2: A | D2: 02 | E2: 05 | F2: BINAAN LUAR | G2: WALKWAY
A3: FLUORESCENT LIGHT WITH LIGHT GUARD | B3: =B2+1 -> 2 | C3: E | D3: 14 | E3: 10 | F3: BINAAN LUAR | G3: BLOK LIGHTING
A4: GUIDING LIGHT | B4: =B3+1 -> 3 | C4: A | D4: 14 | E4: 11 | F4: BINAAN LUAR | G4: SIGNAGE
A5: HENTIAN BAS | B5: =B4+1 -> 4 | C5: A | D5: 02 | E5: 01 | F5: BINAAN LUAR | G5: BUS STOP
A6: SHELTER | B6: =B5+1 -> 5 | C6: A | D6: 02 | E6: 01 | F6: BINAAN LUAR | G6: SHELTER
A7: WATER FEATURES | B7: =B6+1 -> 6 | C7: M | D7: 27 | E7: 02 | F7: BINAAN LUAR | G7: WATER FEATURES
A8: CANVAS CANOPY | B8: =B7+1 -> 7 | C8: A | D8: 09 | E8: 01 | F8: BINAAN LUAR | G8: CANOPY
A9: HIASAN LANDSKAP | B9: =B8+1 -> 8 | C9: A | D9: 09 | E9: 02 | F9: BINAAN LUAR | G9: LANDSCAPE
A10: PLAYGROUND SURFACE EPDM | B10: =B9+1 -> 9 | C10: A | D10: 09 | E10: 01 | F10: BINAAN LUAR | G10: FLOOR FINISHES
A11: CONCRETE PAVING - MODULE 1(INSITU CONCRETE, BROOM FINISH) | B11: =B10+1 -> 10 | C11: A | D11: 09 | E11: 01 | F11: BINAAN LUAR | G11: FLOOR FINISHES
A12: CONCRETE PAVING - MODULE 2 (EXPOSED AGGREGATE) | B12: =B11+1 -> 11 | C12: A | D12: 09 | E12: 01 | F12: BINAAN LUAR | G12: FLOOR FINISHES
A13: CONCRETE PAVING - MODULE 3 (PEBBLE WASH) | B13: =B12+1 -> 12 | C13: A | D13: 09 | E13: 01 | F13: BINAAN LUAR | G13: FLOOR FINISHES
A14: CONCRETE PAVING - MODULE 4 (100X100 UNIT PAVER) | B14: =B13+1 -> 13 | C14: A | D14: 09 | E14: 01 | F14: BINAAN LUAR | G14: FLOOR FINISHES
... A415: RAILING TYPE 05 SLIDING - STANDARD (HOT-DIPPED GALVANISED VERTICAL STEEL FRAME WITH SLIDING BRACKET) | B415: =B414+1 -> 414 | C415: A | D415: 08 | E415: 04 | F415: BINAAN LUAR | G415: RAILING

Sheet MASTER_ARAS_RUANG
A1: NAMA ARAS | B1: KOD ARAS | C1: NAMA RUANG | D1: KOD RUANG
A2: ARAS LANTAI | B2: 00 | C2: ROL P7 - ZON 1 | D2: 01 | E2: TA0140 | F2: =CONCATENATE(E2,".","00",".",D2) -> TA0140.00.01 | G2: Overhead Crossing | H2: =CONCATENATE(G2," - ",C2) -> Overhead Crossing - ROL P7 - ZON 1
A3: ARAS SATU | B3: 01 | C3: ROL P7 - ZON 2 | D3: 02 | E3: TA0140 | F3: =CONCATENATE(E3,".","00",".",D3) -> TA0140.00.02 | G3: Overhead Crossing | H3: =CONCATENATE(G3," - ",C3) -> Overhead Crossing - ROL P7 - ZON 2
A4: ARAS DUA | B4: 02 | C4: ROL P7 - ZON 3 | D4: 03 | E4: TA0140 | F4: =CONCATENATE(E4,".","00",".",D4) -> TA0140.00.03 | G4: Overhead Crossing | H4: =CONCATENATE(G4," - ",C4) -> Overhead Crossing - ROL P7 - ZON 3
A5: ARAS BAWAH TANAH | B5: 03 | C5: ROL P7 - ZON 4 | D5: 04 | E5: TA0140 | F5: =CONCATENATE(E5,".","00",".",D5) -> TA0140.00.04 | G5: Overhead Crossing | H5: =CONCATENATE(G5," - ",C5) -> Overhead Crossing - ROL P7 - ZON 4
C6: ROL P7 - ZON 5 | D6: 05 | E6: TA0140 | F6: =CONCATENATE(E6,".","00",".",D6) -> TA0140.00.05 | G6: Overhead Crossing | H6: =CONCATENATE(G6," - ",C6) -> Overhead Crossing - ROL P7 - ZON 5
C7: ROL P7 - ZON 6 | D7: 06 | E7: TA0140 | F7: =CONCATENATE(E7,".","00",".",D7) -> TA0140.00.06 | G7: Overhead Crossing | H7: =CONCATENATE(G7," - ",C7) -> Overhead Crossing - ROL P7 - ZON 6
C8: ROL PHASE 3A3B - 3A ZON 1 | D8: 07 | E8: TA0140 | F8: =CONCATENATE(E8,".","00",".",D8) -> TA0140.00.07 | G8: Overhead Crossing | H8: =CONCATENATE(G8," - ",C8) -> Overhead Crossing - ROL PHASE 3A3B - 3A ZON 1
C9: ROL PHASE 3A3B - 3A ZON 2 | D9: 08 | E9: TA0140 | F9: =CONCATENATE(E9,".","00",".",D9) -> TA0140.00.08 | G9: Overhead Crossing | H9: =CONCATENATE(G9," - ",C9) -> Overhead Crossing - ROL PHASE 3A3B - 3A ZON 2
C10: ROL PHASE 3A3B - 3A ZON 3 | D10: 09 | E10: TA0140 | F10: =CONCATENATE(E10,".","00",".",D10) -> TA0140.00.09 | G10: Overhead Crossing | H10: =CONCATENATE(G10," - ",C10) -> Overhead Crossing - ROL PHASE 3A3B - 3A ZON 3
C11: ROL PHASE 3A3B - 3A ZON 4 | D11: 10 | E11: TA0140 | F11: =CONCATENATE(E11,".","00",".",D11) -> TA0140.00.10 | G11: Overhead Crossing | H11: =CONCATENATE(G11," - ",C11) -> Overhead Crossing - ROL PHASE 3A3B - 3A ZON 4
C12: ROL PHASE 3A3B - 3B ZON 1 | D12: 11 | E12: TA0140 | F12: =CONCATENATE(E12,".","00",".",D12) -> TA0140.00.11 | G12: Overhead Crossing | H12: =CONCATENATE(G12," - ",C12) -> Overhead Crossing - ROL PHASE 3A3B - 3B ZON 1
C13: ROL PHASE 3A3B - 3B ZON 2 | D13: 12 | E13: TA0140 | F13: =CONCATENATE(E13,".","00",".",D13) -> TA0140.00.12 | G13: Overhead Crossing | H13: =CONCATENATE(G13," - ",C13) -> Overhead Crossing - ROL PHASE 3A3B - 3B ZON 2
C14: ROL PHASE 3A3B - 3B ZON 3 | D14: 13 | E14: TA0140 | F14: =CONCATENATE(E14,".","00",".",D14) -> TA0140.00.13 | G14: Overhead Crossing | H14: =CONCATENATE(G14," - ",C14) -> Overhead Crossing - ROL PHASE 3A3B - 3B ZON 3
C15: ROL 1C1D - ZON 1C (i) | D15: 14 | E15: TA0140 | F15: =CONCATENATE(E15,".","00",".",D15) -> TA0140.00.14 | G15: Overhead Crossing | H15: =CONCATENATE(G15," - ",C15) -> Overhead Crossing - ROL 1C1D - ZON 1C (i)
C16: ROL 1C1D - ZON 1C (ii) | D16: 15 | E16: TA0140 | F16: =CONCATENATE(E16,".","00",".",D16) -> TA0140.00.15 | G16: Overhead Crossing | H16: =CONCATENATE(G16," - ",C16) -> Overhead Crossing - ROL 1C1D - ZON 1C (ii)
C17: ROL 1C1D - ZON 1D | D17: 16 | E17: TA0140 | F17: =CONCATENATE(E17,".","00",".",D17) -> TA0140.00.16 | G17: Overhead Crossing | H17: =CONCATENATE(G17," - ",C17) -> Overhead Crossing - ROL 1C1D - ZON 1D
C18: ROL 4A4B - ZON 1 4A | D18: 17 | E18: TA0140 | F18: =CONCATENATE(E18,".","00",".",D18) -> TA0140.00.17 | G18: Overhead Crossing | H18: =CONCATENATE(G18," - ",C18) -> Overhead Crossing - ROL 4A4B - ZON 1 4A
C19: ROL 4A4B - ZON 2 4B | D19: 18 | E19: TA0140 | F19: =CONCATENATE(E19,".","00",".",D19) -> TA0140.00.18 | G19: Overhead Crossing | H19: =CONCATENATE(G19," - ",C19) -> Overhead Crossing - ROL 4A4B - ZON 2 4B
C20: TITIWANGSA - SISIR BARAT | D20: 19 | E20: TA0140 | F20: =CONCATENATE(E20,".","00",".",D20) -> TA0140.00.19 | G20: Overhead Crossing | H20: =CONCATENATE(G20," - ",C20) -> Overhead Crossing - TITIWANGSA - SISIR BARAT
C21: TITIWANGSA - SISIR TIMUR | D21: 20 | E21: TA0140 | F21: =CONCATENATE(E21,".","00",".",D21) -> TA0140.00.20 | G21: Overhead Crossing | H21: =CONCATENATE(G21," - ",C21) -> Overhead Crossing - TITIWANGSA - SISIR TIMUR
C22: ROL 4A4B - ZON 1 4A - UTILITY ROOM | D22: 17A
C23: ROL 1C1D - ZON 1D - PUMP HOUSE | D23: 16A

Sheet DATA_PEMANTAU
A1: Tarikh | B1: Jenis Aset | C1: Nama Blok/BL | D1: Nama Komponen | E1: Kategori Komponen | F1: ID Komp | G1: Bidang | H1: Sistem | I1: Subsistem | J1: Aras | K1: Kod Aras | L1: Ruang | M1: Kod Ruang | N1: Bilangan | O1: ID Qty Mula | P1: ID Qty Akhir | Q1: Label Komponen | R1: No DPA & DAK | S1: Koord X | T1: Koord Y | U1: URL Gambar | V1: Ukuran Nilai | W1: Ukuran Unit | X1: Nama | Y1: Email | Z1: Kod Blok | AA1: Kod Binaan Luar | AB1: Kod Fungsi Binaan | AC1: Status Aset | AD1: Nama Pengesah | AE1: Jawatan Pengesah | AF1: URL Sig Pengumpul | AG1: URL Sig Pengesah | AH1: Email Pengesah | AI1: Catatan | AJ1: URL Tandatangan Pengesah | AK1: URL PDF DA6 | AL1: Jawatan Pengisi
A2: 45785.441 | B2: BINAAN LUAR | C2: Landscape | D2: FF01.7– BENCH TYPE 07B FLOW BENCH | E2: {=IFERROR(XLOOKUP(D2, MASTER_KOMPONEN!A:A, MASTER_KOMPONEN!G:G, ""), "")} -> BENCHES | F2: 208 | G2: A | H2: 9 | I2: 1 | J2: ARAS LANTAI | K2: 00 | L2: ROL P7 - ZON 1 | M2: 01 | N2: 2 | O2: 0001 | P2: 0002 | Q2: A0901.0001-0002 | R2: 1101164MYS.140005.BG0002.BG0410.02.00.01.208 | S2: 101°41'36.9"E | T2: 3°09'02.7"N | U2: https://drive.google.com/uc?export=view&id=14gxy8pHBhmnfjvLVikep0M0M__Fu_dRz | X2: MOHD AZUAN BIN MOHD SARIFF | Y2: azuansalwa5960@gmail.com | AA2: BG0410 | AC2: AKTIF | AD2: MUHAMMAD SYAZWI BIN KHUSAIRI | AE2: JURUTERA AWAM, J9 | AG2: https://drive.google.com/file/d/1higsIKBDMSqR5wytlOMo2TtMpXaZx1Zr/view?usp=drivesdk | AH2: msyazwik@gmail.com | AJ2: https://drive.google.com/file/d/1higsIKBDMSqR5wytlOMo2TtMpXaZx1Zr/view?usp=drivesdk | AK2: https://drive.google.com/file/d/18wMbUStO0oRXzZLFz-BcahYaKkP7TMc2/view?usp=drivesdk | AL2: Pembantu Am
A3: 45785.443 | B3: BINAAN LUAR | C3: Landscape | D3: FF01.7 – BENCH TYPE 07A FLOW BENCH | E3: {=IFERROR(XLOOKUP(D3, MASTER_KOMPONEN!A:A, MASTER_KOMPONEN!G:G, ""), "")} -> BENCHES | F3: 207 | G3: A | H3: 9 | I3: 1 | J3: ARAS LANTAI | K3: 00 | L3: ROL P7 - ZON 1 | M3: 01 | N3: 2 | O3: 0001 | P3: 0002 | Q3: A0901.0001-0002 | R3: 1101164MYS.140005.BG0002.BG0410.02.00.01.207 | S3: 101°41'36.9"E | T3: 3°09'02.7"N | U3: https://drive.google.com/uc?export=view&id=1LEajXLHX5yoE7G-74zHCksL5uDiYuMMm | X3: MOHD AZUAN BIN MOHD SARIFF | Y3: azuansalwa5960@gmail.com | AA3: BG0410 | AC3: AKTIF | AD3: MUHAMMAD SYAZWI BIN KHUSAIRI | AE3: JURUTERA AWAM, J9 | AG3: https://drive.google.com/file/d/1higsIKBDMSqR5wytlOMo2TtMpXaZx1Zr/view?usp=drivesdk | AH3: msyazwik@gmail.com | AJ3: https://drive.google.com/file/d/1higsIKBDMSqR5wytlOMo2TtMpXaZx1Zr/view?usp=drivesdk | AK3: https://drive.google.com/file/d/1dTQiWr7Prvx7UMtX1aY00EbmSGEJfu2G/view?usp=drivesdk | AL3: Pembantu Am
A4: 45785.448 | B4: BINAAN LUAR | C4: Landscape | D4: SG05A – IDENTIFICATION MOUNTED SIGNAGE | E4: {=IFERROR(XLOOKUP(D4, MASTER_KOMPONEN!A:A, MASTER_KOMPONEN!G:G, ""), "")} -> SIGNAGE | F4: 284 | G4: A | H4: 8 | I4: 7 | J4: ARAS LANTAI | K4: 00 | L4: ROL P7 - ZON 1 | M4: 01 | N4: 1 | O4: 0001 | P4: 0001 | Q4: A0807.0001-0001 | R4: 1101164MYS.140005.BG0002.BG0410.01.00.01.284 | S4: 101°41'36.9"E | T4: 3°09'02.7"N | U4: https://drive.google.com/uc?export=view&id=1sj9U0sNXGpBIiHnT4p5PPnoayMtcNQ4u | X4: MOHD AZUAN BIN MOHD SARIFF | Y4: azuansalwa5960@gmail.com | AA4: BG0410 | AC4: AKTIF | AD4: MUHAMMAD SYAZWI BIN KHUSAIRI | AE4: JURUTERA AWAM, J9 | AG4: https://drive.google.com/file/d/1higsIKBDMSqR5wytlOMo2TtMpXaZx1Zr/view?usp=drivesdk | AH4: msyazwik@gmail.com | AJ4: https://drive.google.com/file/d/1higsIKBDMSqR5wytlOMo2TtMpXaZx1Zr/view?usp=drivesdk | AK4: https://drive.google.com/file/d/1Cu64QftOqeHAslAsAILk2Hvkyl-QqEfV/view?usp=drivesdk | AL4: Pembantu Am
A5: 45816.438 | B5: BINAAN LUAR | C5: Landscape | D5: FF03.2 – BIN TYPE 02 | E5: {=IFERROR(XLOOKUP(D5, MASTER_KOMPONEN!A:A, MASTER_KOMPONEN!G:G, ""), "")} -> BIN | F5: 246 | G5: A | H5: 9 | I5: 1 | J5: ARAS LANTAI | K5: 00 | L5: ROL P7 - ZON 5 | M5: 05 | N5: 1 | O5: 0001 | P5: 0001 | Q5: A0901.0001-0001 | R5: 1101164MYS.140005.BG0002.BG0410.01.00.05.246 | S5: 101.69446 | T5: 3.1472616 | U5: https://drive.google.com/uc?export=view&id=1e51aDsCbDPxMnijF5y8YfLlIb-goJKG5 | X5: KHAIRUL HAMADI BIN ABDULLAH SANI | Y5: khairulhamadi@gmail.com | AA5: BG0410 | AC5: AKTIF | AD5: MUHAMMAD SYAZWI BIN KHUSAIRI | AE5: JURUTERA AWAM, J9 | AF5: https://drive.google.com/file/d/1TwH8ac0vamZjpCm2V8YFMwD9gEeTvIU_/view?usp=drivesdk | AG5: https://drive.google.com/file/d/1higsIKBDMSqR5wytlOMo2TtMpXaZx1Zr/view?usp=drivesdk | AH5: msyazwik@gmail.com | AJ5: https://drive.google.com/file/d/1higsIKBDMSqR5wytlOMo2TtMpXaZx1Zr/view?usp=drivesdk | AK5: https://drive.google.com/file/d/1Q0hHsKQRNkqB-AyyPoLfDJPWHAPMQ7Sq/view?usp=drivesdk | AL5: PENOLONG PEGAWAI SENIBINA
A6: 45816.438 | B6: BINAAN LUAR | C6: Landscape | D6: FF03.2 – BIN TYPE 02 | E6: {=IFERROR(XLOOKUP(D6, MASTER_KOMPONEN!A:A, MASTER_KOMPONEN!G:G, ""), "")} -> BIN | F6: 246 | G6: A | H6: 9 | I6: 1 | J6: ARAS LANTAI | K6: 00 | L6: ROL P7 - ZON 5 | M6: 05 | N6: 1 | O6: 0002 | P6: 0002 | Q6: A0901.0002-0002 | R6: 1101164MYS.140005.BG0002.BG0410.01.00.05.246 | S6: 101.69446 | T6: 3.1472616 | U6: https://drive.google.com/uc?export=view&id=1fT6RNzOqyVnAcaPCw7lCQpcuTQCh8yrz | X6: KHAIRUL HAMADI BIN ABDULLAH SANI | Y6: khairulhamadi@gmail.com | AA6: BG0410 | AC6: AKTIF | AD6: MUHAMMAD SYAZWI BIN KHUSAIRI | AE6: JURUTERA AWAM, J9 | AF6: https://drive.google.com/file/d/1TwH8ac0vamZjpCm2V8YFMwD9gEeTvIU_/view?usp=drivesdk | AG6: https://drive.google.com/file/d/1higsIKBDMSqR5wytlOMo2TtMpXaZx1Zr/view?usp=drivesdk | AH6: msyazwik@gmail.com | AJ6: https://drive.google.com/file/d/1higsIKBDMSqR5wytlOMo2TtMpXaZx1Zr/view?usp=drivesdk | AK6: https://drive.google.com/file/d/1ozgxfbAn2DAY_kLFr4IJvnPk8s7XfmLS/view?usp=drivesdk | AL6: PENOLONG PEGAWAI SENIBINA
A7: 45816.448 | B7: BINAAN LUAR | C7: Walkway/Pedestrian/Footpath | D7: SG01A – PRIMARY GATEWAY SINAGE | E7: {=IFERROR(XLOOKUP(D7, MASTER_KOMPONEN!A:A, MASTER_KOMPONEN!G:G, ""), "")} -> SIGNAGE | F7: 275 | G7: A | H7: 8 | I7: 7 | J7: ARAS LANTAI | K7: 00 | L7: ROL P7 - ZON 4 | M7: 04 | N7: 1 | O7: 0001 | P7: 0001 | Q7: A0807.0001-0001 | R7: 1101164MYS.140005.BG0002.TA0112.01.00.04.275 | S7: 101.69462 | T7: 3.1496288 | U7: https://drive.google.com/uc?export=view&id=15DwG6yS7XuN2NMRC8Rvpo0ydR63FqrCz | X7: MOHD YAZID BIN JAHARI | Y7: yaziddbkl@gmail.com | AA7: TA0112 | AC7: AKTIF | AD7: MUHAMMAD SYAZWI BIN KHUSAIRI | AE7: JURUTERA AWAM, J9 | AF7: https://drive.google.com/file/d/17N6scyltml3TkIDU8BTXsljgeOy0_LG0/view?usp=drivesdk | AG7: https://drive.google.com/file/d/1higsIKBDMSqR5wytlOMo2TtMpXaZx1Zr/view?usp=drivesdk | AH7: msyazwik@gmail.com | AJ7: https://drive.google.com/file/d/1higsIKBDMSqR5wytlOMo2TtMpXaZx1Zr/view?usp=drivesdk | AK7: https://drive.google.com/file/d/1Wy0VBfhIhpFT_GfxOA3Gvw7323u1ndNR/view?usp=drivesdk | AL7: PENOLONG PEGAWAI SENIBINA
A8: 45816.448 | B8: BINAAN LUAR | C8: Walkway/Pedestrian/Footpath | D8: LT01.15 - STREET LIGHT TYPE 15 SCHREDER HESTIA LED WITH ATTACHED ELEMENTS (SINGLE LAMP) | E8: {=IFERROR(XLOOKUP(D8, MASTER_KOMPONEN!A:A, MASTER_KOMPONEN!G:G, ""), "")} -> STREET LIGHTING | F8: 305 | G8: E | H8: 14 | I8: 11 | J8: ARAS LANTAI | K8: 00 | L8: ROL P7 - ZON 5 | M8: 05 | N8: 1 | O8: 0001 | P8: 0001 | Q8: E1411.0001-0001 | R8: 1101164MYS.140005.BG0002.TA0112.01.00.05.305 | S8: 101.69458 | T8: 3.1469195 | U8: https://drive.google.com/uc?export=view&id=1lOgyIQpATRIxFxAZQu9_k5Z3Q0MpuS70 | X8: KHAIRUL HAMADI BIN ABDULLAH SANI | Y8: khairulhamadi@gmail.com | AA8: TA0112 | AC8: AKTIF | AD8: MUHAMMAD SYAZWI BIN KHUSAIRI | AE8: JURUTERA AWAM, J9 | AF8: https://drive.google.com/file/d/1TwH8ac0vamZjpCm2V8YFMwD9gEeTvIU_/view?usp=drivesdk | AG8: https://drive.google.com/file/d/1higsIKBDMSqR5wytlOMo2TtMpXaZx1Zr/view?usp=drivesdk | AH8: msyazwik@gmail.com | AJ8: https://drive.google.com/file/d/1higsIKBDMSqR5wytlOMo2TtMpXaZx1Zr/view?usp=drivesdk | AK8: https://drive.google.com/file/d/1YvCGtwu_lHt4-HS7os-8zz8tuju6icyn/view?usp=drivesdk | AL8: PENOLONG PEGAWAI SENIBINA
A9: 45816.45 | B9: BINAAN LUAR | C9: Walkway/Pedestrian/Footpath | D9: LT01.15 - STREET LIGHT TYPE 15 SCHREDER HESTIA LED WITH ATTACHED ELEMENTS (SINGLE LAMP) | E9: {=IFERROR(XLOOKUP(D9, MASTER_KOMPONEN!A:A, MASTER_KOMPONEN!G:G, ""), "")} -> STREET LIGHTING | F9: 305 | G9: E | H9: 14 | I9: 11 | J9: ARAS LANTAI | K9: 00 | L9: ROL P7 - ZON 5 | M9: 05 | N9: 1 | O9: 0002 | P9: 0002 | Q9: E1411.0002-0002 | R9: 1101164MYS.140005.BG0002.TA0112.01.00.05.305 | S9: 101.6946 | T9: 3.1470493 | U9: https://drive.google.com/uc?export=view&id=17HYEvsjD1a25pH_0Qqu4n9ztSHY_gm3Z | X9: KHAIRUL HAMADI BIN ABDULLAH SANI | Y9: khairulhamadi@gmail.com | AA9: TA0112 | AC9: AKTIF | AD9: MUHAMMAD SYAZWI BIN KHUSAIRI | AE9: JURUTERA AWAM, J9 | AF9: https://drive.google.com/file/d/1TwH8ac0vamZjpCm2V8YFMwD9gEeTvIU_/view?usp=drivesdk | AG9: https://drive.google.com/file/d/1higsIKBDMSqR5wytlOMo2TtMpXaZx1Zr/view?usp=drivesdk | AH9: msyazwik@gmail.com | AJ9: https://drive.google.com/file/d/1higsIKBDMSqR5wytlOMo2TtMpXaZx1Zr/view?usp=drivesdk | AK9: https://drive.google.com/file/d/1bQEb3FqqSxqPVDR3rvup1Q3EkreAqba8/view?usp=drivesdk | AL9: PENOLONG PEGAWAI SENIBINA
A10: 45816.453 | B10: BINAAN LUAR | C10: Landscape | D10: LT04.1 - UPLIGHT TYPE 01 IGUZZINI | E10: {=IFERROR(XLOOKUP(D10, MASTER_KOMPONEN!A:A, MASTER_KOMPONEN!G:G, ""), "")} -> WALKWAY LIGHTING | F10: 322 | G10: E | H10: 14 | I10: 11 | J10: ARAS LANTAI | K10: 00 | L10: ROL P7 - ZON 4 | M10: 04 | N10: 14 | O10: 0001 | P10: 0014 | Q10: E1411.0001-0014 | R10: 1101164MYS.140005.BG0002.BG0410.14.00.04.322 | S10: 101.69457 | T10: 3.1495551071644683, | U10: https://drive.google.com/uc?export=view&id=1MtPlfm7Eg74usU2-E1Z_5VJHKQY6w-Sh | X10: MOHD YAZID BIN JAHARI | Y10: yaziddbkl@gmail.com | AA10: BG0410 | AC10: AKTIF | AD10: MUHAMMAD SYAZWI BIN KHUSAIRI | AE10: JURUTERA AWAM, J9 | AF10: https://drive.google.com/file/d/17N6scyltml3TkIDU8BTXsljgeOy0_LG0/view?usp=drivesdk | AG10: https://drive.google.com/file/d/1higsIKBDMSqR5wytlOMo2TtMpXaZx1Zr/view?usp=drivesdk | AH10: msyazwik@gmail.com | AJ10: https://drive.google.com/file/d/1higsIKBDMSqR5wytlOMo2TtMpXaZx1Zr/view?usp=drivesdk | AK10: https://drive.google.com/file/d/1QBkSpwlhIsX5gl0j2jXNp-Tl4Wrd3BHY/view?usp=drivesdk | AL10: PENOLONG PEGAWAI SENIBINA
A11: 45816.455 | B11: BINAAN LUAR | C11: Landscape | D11: FF01.11– BENCH TYPE 11A ESCOFET SOCRATES | E11: {=IFERROR(XLOOKUP(D11, MASTER_KOMPONEN!A:A, MASTER_KOMPONEN!G:G, ""), "")} -> BENCHES | F11: 214 | G11: A | H11: 9 | I11: 1 | J11: ARAS LANTAI | K11: 00 | L11: ROL P7 - ZON 4 | M11: 04 | N11: 2 | O11: 0001 | P11: 0002 | Q11: A0901.0001-0002 | R11: 1101164MYS.140005.BG0002.BG0410.02.00.04.214 | S11: 101.69457 | T11: 3.1495551071644683, | U11: https://drive.google.com/uc?export=view&id=14LdGh2pWa1ybzEA59FK128FdkvQO5hsS | X11: MOHD YAZID BIN JAHARI | Y11: yaziddbkl@gmail.com | AA11: BG0410 | AC11: AKTIF | AD11: MUHAMMAD SYAZWI BIN KHUSAIRI | AE11: JURUTERA AWAM, J9 | AF11: https://drive.google.com/file/d/17N6scyltml3TkIDU8BTXsljgeOy0_LG0/view?usp=drivesdk | AG11: https://drive.google.com/file/d/1higsIKBDMSqR5wytlOMo2TtMpXaZx1Zr/view?usp=drivesdk | AH11: msyazwik@gmail.com | AJ11: https://drive.google.com/file/d/1higsIKBDMSqR5wytlOMo2TtMpXaZx1Zr/view?usp=drivesdk | AK11: https://drive.google.com/file/d/1HfJALb3f1Rw_Rdbe11wCRPdwsLa2HTRr/view?usp=drivesdk | AL11: PENOLONG PEGAWAI SENIBINA
A12: 45816.457 | B12: BINAAN LUAR | C12: Landscape | D12: LT04.3 - UPLIGHT TYPE 03 IGUZZINI | E12: {=IFERROR(XLOOKUP(D12, MASTER_KOMPONEN!A:A, MASTER_KOMPONEN!G:G, ""), "")} -> WALKWAY LIGHTING | F12: 324 | G12: E | H12: 14 | I12: 11 | J12: ARAS LANTAI | K12: 00 | L12: ROL P7 - ZON 4 | M12: 04 | N12: 4 | O12: 0001 | P12: 0004 | Q12: E1411.0001-0004 | R12: 1101164MYS.140005.BG0002.BG0410.04.00.04.324 | S12: 101.69456 | T12: 3.1496234001797614, | U12: https://drive.google.com/uc?export=view&id=1TdR9s9JnZ-GDywNzF8UGkfBq1C8ccWtY | X12: MOHD YAZID BIN JAHARI | Y12: yaziddbkl@gmail.com | AA12: BG0410 | AC12: AKTIF | AD12: MUHAMMAD SYAZWI BIN KHUSAIRI | AE12: JURUTERA AWAM, J9 | AF12: https://drive.google.com/file/d/17N6scyltml3TkIDU8BTXsljgeOy0_LG0/view?usp=drivesdk | AG12: https://drive.google.com/file/d/1higsIKBDMSqR5wytlOMo2TtMpXaZx1Zr/view?usp=drivesdk | AH12: msyazwik@gmail.com | AJ12: https://drive.google.com/file/d/1higsIKBDMSqR5wytlOMo2TtMpXaZx1Zr/view?usp=drivesdk | AK12: https://drive.google.com/file/d/16pK79C51efMeMFHOLcRTZJG3aO7eXYWX/view?usp=drivesdk | AL12: PENOLONG PEGAWAI SENIBINA
A13: 45816.459 | B13: BINAAN LUAR | C13: Landscape | D13: FF09.4 – TREE GRATE TYPE 04 | E13: {=IFERROR(XLOOKUP(D13, MASTER_KOMPONEN!A:A, MASTER_KOMPONEN!G:G, ""), "")} -> LANDSCAPE | F13: 258 | G13: A | H13: 9 | I13: 1 | J13: ARAS LANTAI | K13: 00 | L13: ROL P7 - ZON 4 | M13: 04 | N13: 6 | O13: 0001 | P13: 0006 | Q13: A0901.0001-0006 | R13: 1101164MYS.140005.BG0002.BG0410.06.00.04.258 | S13: 101.69465 | T13: 3.14953368190383, | U13: https://drive.google.com/uc?export=view&id=1ADQV6pP-ac5MKXyOHyGwvkpJyuDBC83f | X13: MOHD YAZID BIN JAHARI | Y13: yaziddbkl@gmail.com | AA13: BG0410 | AC13: AKTIF | AD13: MUHAMMAD SYAZWI BIN KHUSAIRI | AE13: JURUTERA AWAM, J9 | AF13: https://drive.google.com/file/d/17N6scyltml3TkIDU8BTXsljgeOy0_LG0/view?usp=drivesdk | AG13: https://drive.google.com/file/d/1higsIKBDMSqR5wytlOMo2TtMpXaZx1Zr/view?usp=drivesdk | AH13: msyazwik@gmail.com | AJ13: https://drive.google.com/file/d/1higsIKBDMSqR5wytlOMo2TtMpXaZx1Zr/view?usp=drivesdk | AK13: https://drive.google.com/file/d/1MvBJR_FEsq_UZ92aB9lzn67Cc286K63_/view?usp=drivesdk | AL13: PENOLONG PEGAWAI SENIBINA
A14: 45816.462 | B14: BINAAN LUAR | C14: Landscape | D14: FF02.1– PLANTER SEAT TYPE 01 WITHOUT BACKREST | E14: {=IFERROR(XLOOKUP(D14, MASTER_KOMPONEN!A:A, MASTER_KOMPONEN!G:G, ""), "")} -> BENCHES | F14: 242 | G14: A | H14: 9 | I14: 1 | J14: ARAS LANTAI | K14: 00 | L14: ROL P7 - ZON 4 | M14: 04 | N14: 1 | O14: 0001 | P14: 0001 | Q14: A0901.0001-0001 | R14: 1101164MYS.140005.BG0002.BG0410.01.00.04.242 | S14: 101.69459 | T14: 3.1496689288541435, | U14: https://drive.google.com/uc?export=view&id=1b2esYBKHVyGNV67RZF4-oiIsxCiXDD7m | X14: MOHD YAZID BIN JAHARI | Y14: yaziddbkl@gmail.com | AA14: BG0410 | AC14: AKTIF | AD14: MUHAMMAD SYAZWI BIN KHUSAIRI | AE14: JURUTERA AWAM, J9 | AF14: https://drive.google.com/file/d/17N6scyltml3TkIDU8BTXsljgeOy0_LG0/view?usp=drivesdk | AG14: https://drive.google.com/file/d/1higsIKBDMSqR5wytlOMo2TtMpXaZx1Zr/view?usp=drivesdk | AH14: msyazwik@gmail.com | AJ14: https://drive.google.com/file/d/1higsIKBDMSqR5wytlOMo2TtMpXaZx1Zr/view?usp=drivesdk | AK14: https://drive.google.com/file/d/176czIzdxkb16dIoJ2ucMMGBIrv1NHWTV/view?usp=drivesdk | AL14: PENOLONG PEGAWAI SENIBINA
A15: 45816.463 | B15: BINAAN LUAR | C15: Landscape | D15: FF02.1– PLANTER SEAT TYPE 01 WITHOUT BACKREST | E15: {=IFERROR(XLOOKUP(D15, MASTER_KOMPONEN!A:A, MASTER_KOMPONEN!G:G, ""), "")} -> BENCHES | F15: 242 | G15: A | H15: 9 | I15: 1 | J15: ARAS LANTAI | K15: 00 | L15: ROL P7 - ZON 1 | M15: 01 | N15: 3 | O15: 0001 | P15: 0003 | Q15: A0901.0001-0003 | R15: 1101164MYS.140005.BG0002.BG0410.03.00.01.242 | S15: 101°41'36.9"E | T15: 3°09'02.7"N | U15: https://drive.google.com/uc?export=view&id=11qkBErlu3t9JqhpbxjPqMhljP8XbsSZt | X15: MOHD AZUAN BIN MOHD SARIFF | Y15: azuansalwa5960@gmail.com | AA15: BG0410 | AC15: AKTIF | AD15: MUHAMMAD SYAZWI BIN KHUSAIRI | AE15: JURUTERA AWAM, J9 | AG15: https://drive.google.com/file/d/1higsIKBDMSqR5wytlOMo2TtMpXaZx1Zr/view?usp=drivesdk | AH15: msyazwik@gmail.com | AJ15: https://drive.google.com/file/d/1higsIKBDMSqR5wytlOMo2TtMpXaZx1Zr/view?usp=drivesdk | AK15: https://drive.google.com/file/d/1RYC8byhPyqTjM4Yq1lV88RS-ogvb2vtI/view?usp=drivesdk | AL15: Pembantu Am
A16: 45816.465 | B16: BINAAN LUAR | C16: Landscape | D16: FF01.11– BENCH TYPE 11A ESCOFET SOCRATES | E16: {=IFERROR(XLOOKUP(D16, MASTER_KOMPONEN!A:A, MASTER_KOMPONEN!G:G, ""), "")} -> BENCHES | F16: 214 | G16: A | H16: 9 | I16: 1 | J16: ARAS LANTAI | K16: 00 | L16: ROL P7 - ZON 1 | M16: 01 | N16: 7 | O16: 0001 | P16: 0007 | Q16: A0901.0001-0007 | R16: 1101164MYS.140005.BG0002.BG0410.07.00.01.214 | S16: 101°41'36.9"E | T16: 3°09'02.7"N | U16: https://drive.google.com/uc?export=view&id=1c8Z-6PIjUvKCfVb1LLe4nuAJrBsomRZk | X16: MOHD AZUAN BIN MOHD SARIFF | Y16: azuansalwa5960@gmail.com | AA16: BG0410 | AC16: AKTIF | AD16: MUHAMMAD SYAZWI BIN KHUSAIRI | AE16: JURUTERA AWAM, J9 | AG16: https://drive.google.com/file/d/1higsIKBDMSqR5wytlOMo2TtMpXaZx1Zr/view?usp=drivesdk | AH16: msyazwik@gmail.com | AJ16: https://drive.google.com/file/d/1higsIKBDMSqR5wytlOMo2TtMpXaZx1Zr/view?usp=drivesdk | AK16: https://drive.google.com/file/d/1kvyiuhbXnwdWjc6GLd6CB-ucJ5F9gZ_8/view?usp=drivesdk | AL16: Pembantu Am
A17: 45816.467 | B17: BINAAN LUAR | C17: Walkway/Pedestrian/Footpath | D17: RAILING TYPE 10 , 11 & 12 RIVERFRONT ALONG HERITAGE AREA | E17: {=IFERROR(XLOOKUP(D17, MASTER_KOMPONEN!A:A, MASTER_KOMPONEN!G:G, ""), "")} -> RAILING | F17: 194 | G17: A | H17: 9 | I17: 1 | J17: ARAS LANTAI | K17: 00 | L17: ROL P7 - ZON 4 | M17: 04 | N17: 1 | O17: 0001 | P17: 0001 | Q17: A0901.0001-0001 | R17: 1101164MYS.140005.BG0002.TA0112.01.00.04.194 | S17: 101.69474 | T17: 3.149552052544829, | U17: https://drive.google.com/uc?export=view&id=1Y21CT-CdqGjnvisAXqu-vGcCP2C_RBbo | X17: MOHD YAZID BIN JAHARI | Y17: yaziddbkl@gmail.com | AA17: TA0112 | AC17: AKTIF | AD17: MUHAMMAD SYAZWI BIN KHUSAIRI | AE17: JURUTERA AWAM, J9 | AF17: https://drive.google.com/file/d/17N6scyltml3TkIDU8BTXsljgeOy0_LG0/view?usp=drivesdk | AG17: https://drive.google.com/file/d/1higsIKBDMSqR5wytlOMo2TtMpXaZx1Zr/view?usp=drivesdk | AH17: msyazwik@gmail.com | AJ17: https://drive.google.com/file/d/1higsIKBDMSqR5wytlOMo2TtMpXaZx1Zr/view?usp=drivesdk | AK17: https://drive.google.com/file/d/1qZ4IG-fIFZGK9EWS8SRM8Ya7RveDz5pH/view?usp=drivesdk | AL17: PENOLONG PEGAWAI SENIBINA
A18: 45816.468 | B18: BINAAN LUAR | C18: Landscape | D18: FF03.2 – BIN TYPE 02 | E18: {=IFERROR(XLOOKUP(D18, MASTER_KOMPONEN!A:A, MASTER_KOMPONEN!G:G, ""), "")} -> BIN | F18: 246 | G18: A | H18: 9 | I18: 1 | J18: ARAS LANTAI | K18: 00 | L18: ROL P7 - ZON 1 | M18: 01 | N18: 3 | O18: 0001 | P18: 0003 | Q18: A0901.0001-0003 | R18: 1101164MYS.140005.BG0002.BG0410.03.00.01.246 | S18: 101°41'39.1"E | T18: 3°09'03.5"N | U18: https://drive.google.com/uc?export=view&id=1z5jke2Dy4rYjOmx35P9xoDTtrvF4oAGC | X18: MOHD AZUAN BIN MOHD SARIFF | Y18: azuansalwa5960@gmail.com | AA18: BG0410 | AC18: AKTIF | AD18: MUHAMMAD SYAZWI BIN KHUSAIRI | AE18: JURUTERA AWAM, J9 | AG18: https://drive.google.com/file/d/1higsIKBDMSqR5wytlOMo2TtMpXaZx1Zr/view?usp=drivesdk | AH18: msyazwik@gmail.com | AJ18: https://drive.google.com/file/d/1higsIKBDMSqR5wytlOMo2TtMpXaZx1Zr/view?usp=drivesdk | AK18: https://drive.google.com/file/d/1_YvXwB2F4hhbhVfQpu0SLj-EzwfSmPlZ/view?usp=drivesdk | AL18: Pembantu Am
A19: 45816.7 | B19: BINAAN LUAR | C19: Walkway/Pedestrian/Footpath | D19: SG01A – PRIMARY GATEWAY SINAGE | E19: {=IFERROR(XLOOKUP(D19, MASTER_KOMPONEN!A:A, MASTER_KOMPONEN!G:G, ""), "")} -> SIGNAGE | F19: 275 | G19: A | H19: 8 | I19: 7 | J19: ARAS LANTAI | K19: 00 | L19: ROL P7 - ZON 4 | M19: 04 | N19: 1 | O19: 0002 | P19: 0002 | Q19: A0807.0002-0002 | R19: 1101164MYS.140005.BG0002.TA0112.01.00.04.275 | S19: 101.69471 | T19: 3.1494921704601193, | U19: https://drive.google.com/uc?export=view&id=1HI8IkqHatdttbEYWbEMEU-T15LyhadMb | X19: MOHD YAZID BIN JAHARI | Y19: yaziddbkl@gmail.com | AA19: TA0112 | AC19: AKTIF | AD19: MUHAMMAD SYAZWI BIN KHUSAIRI | AE19: JURUTERA AWAM, J9 | AF19: https://drive.google.com/file/d/17N6scyltml3TkIDU8BTXsljgeOy0_LG0/view?usp=drivesdk | AG19: https://drive.google.com/file/d/1higsIKBDMSqR5wytlOMo2TtMpXaZx1Zr/view?usp=drivesdk | AH19: msyazwik@gmail.com | AJ19: https://drive.google.com/file/d/1higsIKBDMSqR5wytlOMo2TtMpXaZx1Zr/view?usp=drivesdk | AK19: https://drive.google.com/file/d/1CqzkpYtfg_mSGtnQ7Y7yVQLImfCIQhsB/view?usp=drivesdk | AL19: PENOLONG PEGAWAI SENIBINA
A20: 45846.429 | B20: BINAAN LUAR | C20: Walkway/Pedestrian/Footpath | D20: SG03B – PEDESTRIAN DIRECTIONAL TOTEM | E20: {=IFERROR(XLOOKUP(D20, MASTER_KOMPONEN!A:A, MASTER_KOMPONEN!G:G, ""), "")} -> SIGNAGE | F20: 278 | G20: A | H20: 8 | I20: 7 | J20: ARAS LANTAI | K20: 00 | L20: ROL P7 - ZON 5 | M20: 05 | N20: 1 | O20: 0001 | P20: 0001 | Q20: A0807.0001-0001 | R20: 1101164MYS.140005.BG0002.TA0112.01.00.05.278 | S20: 101.69416 | T20: 3.1471577 | U20: https://drive.google.com/uc?export=view&id=1HltMRknLc5wf8RQ3Hm5S4FEQBoFepq3v | X20: FATIMAH BINTI SHOKARI | Y20: fatimahshokari@gmail.com | AA20: TA0112 | AC20: AKTIF | AD20: MUHAMMAD SYAZWI BIN KHUSAIRI | AE20: JURUTERA AWAM, J9 | AF20: https://drive.google.com/file/d/1WQ-UxposFtrKzeteUeprXRTgHFwqUh8E/view?usp=drivesdk | AG20: https://drive.google.com/file/d/1higsIKBDMSqR5wytlOMo2TtMpXaZx1Zr/view?usp=drivesdk | AH20: msyazwik@gmail.com | AJ20: https://drive.google.com/file/d/1higsIKBDMSqR5wytlOMo2TtMpXaZx1Zr/view?usp=drivesdk | AK20: https://drive.google.com/file/d/1lSxOH3TgydItk1ONw4H5IGH9lwwl9-NS/view?usp=drivesdk | AL20: PENOLONG PEGAWAI SENIBINA JA5
A21: 45846.433 | B21: BINAAN LUAR | C21: Walkway/Pedestrian/Footpath | D21: LT01.15 - STREET LIGHT TYPE 15 SCHREDER HESTIA LED WITH ATTACHED ELEMENTS (SINGLE LAMP) | E21: {=IFERROR(XLOOKUP(D21, MASTER_KOMPONEN!A:A, MASTER_KOMPONEN!G:G, ""), "")} -> STREET LIGHTING | F21: 305 | G21: E | H21: 14 | I21: 11 | J21: ARAS LANTAI | K21: 00 | L21: ROL P7 - ZON 5 | M21: 05 | N21: 1 | O21: 0003 | P21: 0003 | Q21: E1411.0003-0003 | R21: 1101164MYS.140005.BG0002.TA0112.01.00.05.305 | S21: 101.69496 | T21: 3.1470254 | U21: https://drive.google.com/uc?export=view&id=1MEmEsyzrlwamdM9VUsl08djww5cdDjI6 | X21: FATIMAH BINTI SHOKARI | Y21: fatimahshokari@gmail.com | AA21: TA0112 | AC21: AKTIF | AD21: MUHAMMAD SYAZWI BIN KHUSAIRI | AE21: JURUTERA AWAM, J9 | AF21: https://drive.google.com/file/d/1WQ-UxposFtrKzeteUeprXRTgHFwqUh8E/view?usp=drivesdk | AG21: https://drive.google.com/file/d/1higsIKBDMSqR5wytlOMo2TtMpXaZx1Zr/view?usp=drivesdk | AH21: msyazwik@gmail.com | AJ21: https://drive.google.com/file/d/1higsIKBDMSqR5wytlOMo2TtMpXaZx1Zr/view?usp=drivesdk | AK21: https://drive.google.com/file/d/1XPwH23fQQVlUdzYKMOEkVoZWnbHsbdXO/view?usp=drivesdk | AL21: PENOLONG PEGAWAI SENIBINA JA5
A22: 45846.436 | B22: BINAAN LUAR | C22: Walkway/Pedestrian/Footpath | D22: FF05.3– BOLLARD TYPE 03 FIXED | E22: {=IFERROR(XLOOKUP(D22, MASTER_KOMPONEN!A:A, MASTER_KOMPONEN!G:G, ""), "")} -> BOLLARD | F22: 253 | G22: A | H22: 9 | I22: 1 | J22: ARAS LANTAI | K22: 00 | L22: ROL P7 - ZON 5 | M22: 05 | N22: 2 | O22: 0001 | P22: 0002 | Q22: A0901.0001-0002 | R22: 1101164MYS.140005.BG0002.TA0112.02.00.05.253 | S22: 101.69487 | T22: 3.1471073 | U22: https://drive.google.com/uc?export=view&id=1THbURAWn3RMEaidlIFWc820nVOi6b6Td | X22: Elyas Mohd Jarami | Y22: elyasdbkl@gmail.com | AA22: TA0112 | AC22: AKTIF | AD22: MUHAMMAD SYAZWI BIN KHUSAIRI | AE22: JURUTERA AWAM, J9 | AF22: https://drive.google.com/file/d/1E6VTZ7moulozcuoRPyeRytD7IVH9Y7zq/view?usp=drivesdk | AG22: https://drive.google.com/file/d/1higsIKBDMSqR5wytlOMo2TtMpXaZx1Zr/view?usp=drivesdk | AH22: msyazwik@gmail.com | AJ22: https://drive.google.com/file/d/1higsIKBDMSqR5wytlOMo2TtMpXaZx1Zr/view?usp=drivesdk | AK22: https://drive.google.com/file/d/1U875RcDdQcL8CgrLS91xD5ciJVIQayyG/view?usp=drivesdk | AL22: Arkitek
A23: 45846.438 | B23: BINAAN LUAR | C23: Walkway/Pedestrian/Footpath | D23: LT01.15 - STREET LIGHT TYPE 15 SCHREDER HESTIA LED WITH ATTACHED ELEMENTS (SINGLE LAMP) | E23: {=IFERROR(XLOOKUP(D23, MASTER_KOMPONEN!A:A, MASTER_KOMPONEN!G:G, ""), "")} -> STREET LIGHTING | F23: 305 | G23: E | H23: 14 | I23: 11 | J23: ARAS LANTAI | K23: 00 | L23: ROL P7 - ZON 5 | M23: 05 | N23: 1 | O23: 0004 | P23: 0004 | Q23: E1411.0004-0004 | R23: 1101164MYS.140005.BG0002.TA0112.01.00.05.305 | S23: 101.69498 | T23: 3.1470037 | U23: https://drive.google.com/uc?export=view&id=19XfhIEnXkWDVzt_w56Jtz_6dpcHiHw6Z | X23: Elyas Mohd Jarami | Y23: elyasdbkl@gmail.com | AA23: TA0112 | AC23: AKTIF | AD23: MUHAMMAD SYAZWI BIN KHUSAIRI | AE23: JURUTERA AWAM, J9 | AF23: https://drive.google.com/file/d/1E6VTZ7moulozcuoRPyeRytD7IVH9Y7zq/view?usp=drivesdk | AG23: https://drive.google.com/file/d/1higsIKBDMSqR5wytlOMo2TtMpXaZx1Zr/view?usp=drivesdk | AH23: msyazwik@gmail.com | AJ23: https://drive.google.com/file/d/1higsIKBDMSqR5wytlOMo2TtMpXaZx1Zr/view?usp=drivesdk | AK23: https://drive.google.com/file/d/15kK-FHqTAcL2qEsUZJxRIX3U34zrTX2W/view?usp=drivesdk | AL23: Arkitek
A24: 45846.439 | B24: BINAAN LUAR | C24: Walkway/Pedestrian/Footpath | D24: SG03B – PEDESTRIAN DIRECTIONAL TOTEM | E24: {=IFERROR(XLOOKUP(D24, MASTER_KOMPONEN!A:A, MASTER_KOMPONEN!G:G, ""), "")} -> SIGNAGE | F24: 278 | G24: A | H24: 8 | I24: 7 | J24: ARAS LANTAI | K24: 00 | L24: ROL P7 - ZON 5 | M24: 05 | N24: 1 | O24: 0002 | P24: 0002 | Q24: A0807.0002-0002 | R24: 1101164MYS.140005.BG0002.TA0112.01.00.05.278 | S24: 101.6948 | T24: 3.1471585 | U24: https://drive.google.com/uc?export=view&id=1ImJPokNy2nayuh7LC78B3poCZZ_Lx5bv | X24: FATIMAH BINTI SHOKARI | Y24: fatimahshokari@gmail.com | AA24: TA0112 | AC24: AKTIF | AD24: MUHAMMAD SYAZWI BIN KHUSAIRI | AE24: JURUTERA AWAM, J9 | AF24: https://drive.google.com/file/d/1WQ-UxposFtrKzeteUeprXRTgHFwqUh8E/view?usp=drivesdk | AG24: https://drive.google.com/file/d/1higsIKBDMSqR5wytlOMo2TtMpXaZx1Zr/view?usp=drivesdk | AH24: msyazwik@gmail.com | AJ24: https://drive.google.com/file/d/1higsIKBDMSqR5wytlOMo2TtMpXaZx1Zr/view?usp=drivesdk | AK24: https://drive.google.com/file/d/1v_LhzCez7G85MFBnc08YzUoFRW9DAXMG/view?usp=drivesdk | AL24: PENOLONG PEGAWAI SENIBINA JA5
A25: 45846.442 | B25: BINAAN LUAR | C25: Walkway/Pedestrian/Footpath | D25: LT01.15 - STREET LIGHT TYPE 15 SCHREDER HESTIA LED WITH ATTACHED ELEMENTS (SINGLE LAMP) | E25: {=IFERROR(XLOOKUP(D25, MASTER_KOMPONEN!A:A, MASTER_KOMPONEN!G:G, ""), "")} -> STREET LIGHTING | F25: 305 | G25: E | H25: 14 | I25: 11 | J25: ARAS LANTAI | K25: 00 | L25: ROL P7 - ZON 5 | M25: 05 | N25: 1 | O25: 0005 | P25: 0005 | Q25: E1411.0005-0005 | R25: 1101164MYS.140005.BG0002.TA0112.01.00.05.305 | S25: 101.69516 | T25: 3.1469966 | U25: https://drive.google.com/uc?export=view&id=1fFQv9bewcsSgxbEwTL3Yk_p9A3-lXya8 | X25: FATIMAH BINTI SHOKARI | Y25: fatimahshokari@gmail.com | AA25: TA0112 | AC25: AKTIF | AD25: MUHAMMAD SYAZWI BIN KHUSAIRI | AE25: JURUTERA AWAM, J9 | AF25: https://drive.google.com/file/d/1WQ-UxposFtrKzeteUeprXRTgHFwqUh8E/view?usp=drivesdk | AG25: https://drive.google.com/file/d/1higsIKBDMSqR5wytlOMo2TtMpXaZx1Zr/view?usp=drivesdk | AH25: msyazwik@gmail.com | AJ25: https://drive.google.com/file/d/1higsIKBDMSqR5wytlOMo2TtMpXaZx1Zr/view?usp=drivesdk | AK25: https://drive.google.com/file/d/1J2xk_B1hx2T3QUPl9yuElRuRNoQgrrn0/view?usp=drivesdk | AL25: PENOLONG PEGAWAI SENIBINA JA5
A26: 45846.445 | B26: BINAAN LUAR | C26: Walkway/Pedestrian/Footpath | D26: LT01.15 - STREET LIGHT TYPE 15 SCHREDER HESTIA LED WITH ATTACHED ELEMENTS (SINGLE LAMP) | E26: {=IFERROR(XLOOKUP(D26, MASTER_KOMPONEN!A:A, MASTER_KOMPONEN!G:G, ""), "")} -> STREET LIGHTING | F26: 305 | G26: E | H26: 14 | I26: 11 | J26: ARAS LANTAI | K26: 00 | L26: ROL P7 - ZON 5 | M26: 05 | N26: 1 | O26: 0006 | P26: 0006 | Q26: E1411.0006-0006 | R26: 1101164MYS.140005.BG0002.TA0112.01.00.05.305 | S26: 101.69528 | T26: 3.1469352 | U26: https://drive.google.com/uc?export=view&id=19gZpYk7NU3c3ZA1opSli56E0yJABAjMI | X26: FATIMAH BINTI SHOKARI | Y26: fatimahshokari@gmail.com | AA26: TA0112 | AC26: AKTIF | AD26: MUHAMMAD SYAZWI BIN KHUSAIRI | AE26: JURUTERA AWAM, J9 | AF26: https://drive.google.com/file/d/1WQ-UxposFtrKzeteUeprXRTgHFwqUh8E/view?usp=drivesdk | AG26: https://drive.google.com/file/d/1higsIKBDMSqR5wytlOMo2TtMpXaZx1Zr/view?usp=drivesdk | AH26: msyazwik@gmail.com | AJ26: https://drive.google.com/file/d/1higsIKBDMSqR5wytlOMo2TtMpXaZx1Zr/view?usp=drivesdk | AK26: https://drive.google.com/file/d/1RrpKO3HLBDnH4ylE6FwYH6XmcroU2hsd/view?usp=drivesdk | AL26: PENOLONG PEGAWAI SENIBINA JA5
A27: 45846.445 | B27: BINAAN LUAR | C27: Walkway/Pedestrian/Footpath | D27: SG03C – PEDESTRIAN DIRECTIONAL TRAIL MARKER | E27: {=IFERROR(XLOOKUP(D27, MASTER_KOMPONEN!A:A, MASTER_KOMPONEN!G:G, ""), "")} -> SIGNAGE | F27: 279 | G27: A | H27: 8 | I27: 7 | J27: ARAS LANTAI | K27: 00 | L27: ROL P7 - ZON 5 | M27: 05 | N27: 1 | O27: 0001 | P27: 0001 | Q27: A0807.0001-0001 | R27: 1101164MYS.140005.BG0002.TA0112.01.00.05.279 | S27: 101.69518 | T27: 3.145710443501332, | U27: https://drive.google.com/uc?export=view&id=1dn9SresCOXgzJgFZ086tJAULIU1dpS5q | X27: Elyas Mohd Jarami | Y27: elyasdbkl@gmail.com | AA27: TA0112 | AC27: AKTIF | AD27: MUHAMMAD SYAZWI BIN KHUSAIRI | AE27: JURUTERA AWAM, J9 | AF27: https://drive.google.com/file/d/1E6VTZ7moulozcuoRPyeRytD7IVH9Y7zq/view?usp=drivesdk | AG27: https://drive.google.com/file/d/1higsIKBDMSqR5wytlOMo2TtMpXaZx1Zr/view?usp=drivesdk | AH27: msyazwik@gmail.com | AJ27: https://drive.google.com/file/d/1higsIKBDMSqR5wytlOMo2TtMpXaZx1Zr/view?usp=drivesdk | AK27: https://drive.google.com/file/d/155mkHkjTdfhOQjWnJO21KWCJLD3w4JHb/view?usp=drivesdk | AL27: Arkitek
A28: 45846.447 | B28: BINAAN LUAR | C28: Walkway/Pedestrian/Footpath | D28: SG03C – PEDESTRIAN DIRECTIONAL TRAIL MARKER | E28: {=IFERROR(XLOOKUP(D28, MASTER_KOMPONEN!A:A, MASTER_KOMPONEN!G:G, ""), "")} -> SIGNAGE | F28: 279 | G28: A | H28: 8 | I28: 7 | J28: ARAS LANTAI | K28: 00 | L28: ROL P7 - ZON 5 | M28: 05 | N28: 1 | O28: 0002 | P28: 0002 | Q28: A0807.0002-0002 | R28: 1101164MYS.140005.BG0002.TA0112.01.00.05.279 | S28: 101.69522 | T28: 3.147036 | U28: https://drive.google.com/uc?export=view&id=1Yn4_oSyYMtUMMYcJfPfRHPkkiADtWJVa | X28: Elyas Mohd Jarami | Y28: elyasdbkl@gmail.com | AA28: TA0112 | AC28: AKTIF | AD28: MUHAMMAD SYAZWI BIN KHUSAIRI | AE28: JURUTERA AWAM, J9 | AF28: https://drive.google.com/file/d/1E6VTZ7moulozcuoRPyeRytD7IVH9Y7zq/view?usp=drivesdk | AG28: https://drive.google.com/file/d/1higsIKBDMSqR5wytlOMo2TtMpXaZx1Zr/view?usp=drivesdk | AH28: msyazwik@gmail.com | AJ28: https://drive.google.com/file/d/1higsIKBDMSqR5wytlOMo2TtMpXaZx1Zr/view?usp=drivesdk | AK28: https://drive.google.com/file/d/1A5vyqHjUl1E2va-NaE0ksWbwHJ7fhkqi/view?usp=drivesdk | AL28: Arkitek
A29: 45846.449 | B29: BINAAN LUAR | C29: Landscape | D29: BOX UP | E29: {=IFERROR(XLOOKUP(D29, MASTER_KOMPONEN!A:A, MASTER_KOMPONEN!G:G, ""), "")} -> WALL FINISHES | F29: 274 | G29: A | H29: 9 | I29: 1 | J29: ARAS LANTAI | K29: 00 | L29: ROL P7 - ZON 5 | M29: 05 | N29: 58 | O29: 0001 | P29: 0058 | Q29: A0901.0001-0058 | R29: 1101164MYS.140005.BG0002.BG0410.58.00.05.274 | S29: 101.69517 | T29: 3.147041531896207, | U29: https://drive.google.com/uc?export=view&id=1PEhUV52CS6WVQG7SCP8yf0N73WbmhJ-F | X29: KHAIRUL HAMADI BIN ABDULLAH SANI | Y29: khairulhamadi@gmail.com | AA29: BG0410 | AC29: AKTIF | AD29: MUHAMMAD SYAZWI BIN KHUSAIRI | AE29: JURUTERA AWAM, J9 | AF29: https://drive.google.com/file/d/1TwH8ac0vamZjpCm2V8YFMwD9gEeTvIU_/view?usp=drivesdk | AG29: https://drive.google.com/file/d/1higsIKBDMSqR5wytlOMo2TtMpXaZx1Zr/view?usp=drivesdk | AH29: msyazwik@gmail.com | AJ29: https://drive.google.com/file/d/1higsIKBDMSqR5wytlOMo2TtMpXaZx1Zr/view?usp=drivesdk | AK29: https://drive.google.com/file/d/1KcPCX3oicwLtkrM7JV-1M1sYaGSEWmZY/view?usp=drivesdk | AL29: PENOLONG PEGAWAI SENIBINA
A30: 45846.45 | B30: BINAAN LUAR | C30: Walkway/Pedestrian/Footpath | D30: LT04.1 - UPLIGHT TYPE 01 IGUZZINI | E30: {=IFERROR(XLOOKUP(D30, MASTER_KOMPONEN!A:A, MASTER_KOMPONEN!G:G, ""), "")} -> WALKWAY LIGHTING | F30: 322 | G30: E | H30: 14 | I30: 11 | J30: ARAS LANTAI | K30: 00 | L30: ROL P7 - ZON 5 | M30: 05 | N30: 3 | O30: 0001 | P30: 0003 | Q30: E1411.0001-0003 | R30: 1101164MYS.140005.BG0002.TA0112.03.00.05.322 | S30: 101.69519 | T30: 3.1468821 | U30: https://drive.google.com/uc?export=view&id=1uaxwkD66gONuTLZDS_s2_p5xIJZvyQOE | X30: Elyas Mohd Jarami | Y30: elyasdbkl@gmail.com | AA30: TA0112 | AC30: AKTIF | AD30: MUHAMMAD SYAZWI BIN KHUSAIRI | AE30: JURUTERA AWAM, J9 | AF30: https://drive.google.com/file/d/1E6VTZ7moulozcuoRPyeRytD7IVH9Y7zq/view?usp=drivesdk | AG30: https://drive.google.com/file/d/1higsIKBDMSqR5wytlOMo2TtMpXaZx1Zr/view?usp=drivesdk | AH30: msyazwik@gmail.com | AJ30: https://drive.google.com/file/d/1higsIKBDMSqR5wytlOMo2TtMpXaZx1Zr/view?usp=drivesdk | AK30: https://drive.google.com/file/d/1Ywulpp3A_WQsfbo8DiyZLCC_SnEHCZoZ/view?usp=drivesdk | AL30: Arkitek
A31: 45846.452 | B31: BINAAN LUAR | C31: Walkway/Pedestrian/Footpath | D31: LT04.1 - UPLIGHT TYPE 01 IGUZZINI | E31: {=IFERROR(XLOOKUP(D31, MASTER_KOMPONEN!A:A, MASTER_KOMPONEN!G:G, ""), "")} -> WALKWAY LIGHTING | F31: 322 | G31: E | H31: 14 | I31: 11 | J31: ARAS LANTAI | K31: 00 | L31: ROL P7 - ZON 5 | M31: 05 | N31: 3 | O31: 0004 | P31: 0006 | Q31: E1411.0004-0006 | R31: 1101164MYS.140005.BG0002.TA0112.03.00.05.322 | S31: 101.69509 | T31: 3.1469294 | U31: https://drive.google.com/uc?export=view&id=1ZZXNTFyeA4NfJJy5vLtO-X-u3x7mdKJW | X31: Elyas Mohd Jarami | Y31: elyasdbkl@gmail.com | AA31: TA0112 | AC31: AKTIF | AD31: MUHAMMAD SYAZWI BIN KHUSAIRI | AE31: JURUTERA AWAM, J9 | AF31: https://drive.google.com/file/d/1E6VTZ7moulozcuoRPyeRytD7IVH9Y7zq/view?usp=drivesdk | AG31: https://drive.google.com/file/d/1higsIKBDMSqR5wytlOMo2TtMpXaZx1Zr/view?usp=drivesdk | AH31: msyazwik@gmail.com | AJ31: https://drive.google.com/file/d/1higsIKBDMSqR5wytlOMo2TtMpXaZx1Zr/view?usp=drivesdk | AK31: https://drive.google.com/file/d/1xjKRNTsSMRgkkPVxyo4s_RiSztZmr-91/view?usp=drivesdk | AL31: Arkitek
A32: 45846.452 | B32: BINAAN LUAR | C32: Walkway/Pedestrian/Footpath | D32: LT02.2 - PEDESTRIAN LIGHT TYPE 02 IGUZZINI CUSTOM DESIGN (SINGLE SIDE) | E32: {=IFERROR(XLOOKUP(D32, MASTER_KOMPONEN!A:A, MASTER_KOMPONEN!G:G, ""), "")} -> WALKWAY LIGHTING | F32: 311 | G32: E | H32: 14 | I32: 10 | J32: ARAS LANTAI | K32: 00 | L32: ROL P7 - ZON 5 | M32: 05 | N32: 2 | O32: 0001 | P32: 0002 | Q32: E1410.0001-0002 | R32: 1101164MYS.140005.BG0002.TA0112.02.00.05.311 | S32: 101.69526 | T32: 3.1466203 | U32: https://drive.google.com/uc?export=view&id=1hFze4kXDf9yU0fFvEMqUX4PVDMcNe27T | X32: FATIMAH BINTI SHOKARI | Y32: fatimahshokari@gmail.com | AA32: TA0112 | AC32: AKTIF | AD32: MUHAMMAD SYAZWI BIN KHUSAIRI | AE32: JURUTERA AWAM, J9 | AF32: https://drive.google.com/file/d/1WQ-UxposFtrKzeteUeprXRTgHFwqUh8E/view?usp=drivesdk | AG32: https://drive.google.com/file/d/1higsIKBDMSqR5wytlOMo2TtMpXaZx1Zr/view?usp=drivesdk | AH32: msyazwik@gmail.com | AJ32: https://drive.google.com/file/d/1higsIKBDMSqR5wytlOMo2TtMpXaZx1Zr/view?usp=drivesdk | AK32: https://drive.google.com/file/d/1DgnuA92m5jNB4sQRzIhs0bopmWrLNWgj/view?usp=drivesdk | AL32: PENOLONG PEGAWAI SENIBINA JA5
A33: 45846.452 | B33: BINAAN LUAR | C33: Walkway/Pedestrian/Footpath | D33: SINAGE - GUIDING LIGHT | E33: {=IFERROR(XLOOKUP(D33, MASTER_KOMPONEN!A:A, MASTER_KOMPONEN!G:G, ""), "")} -> SIGNAGE | F33: 287 | G33: A | H33: 8 | I33: 7 | J33: ARAS LANTAI | K33: 00 | L33: ROL P7 - ZON 5 | M33: 05 | N33: 1 | O33: 0001 | P33: 0001 | Q33: A0807.0001-0001 | R33: 1101164MYS.140005.BG0002.TA0112.01.00.05.287 | S33: 101.69519 | T33: 3.147084804952085, | U33: https://drive.google.com/uc?export=view&id=1jTmeDQw4azlYrchBArp5MVO1o1aPXIc4 | X33: KHAIRUL HAMADI BIN ABDULLAH SANI | Y33: khairulhamadi@gmail.com | AA33: TA0112 | AC33: AKTIF | AD33: MUHAMMAD SYAZWI BIN KHUSAIRI | AE33: JURUTERA AWAM, J9 | AF33: https://drive.google.com/file/d/1TwH8ac0vamZjpCm2V8YFMwD9gEeTvIU_/view?usp=drivesdk | AG33: https://drive.google.com/file/d/1higsIKBDMSqR5wytlOMo2TtMpXaZx1Zr/view?usp=drivesdk | AH33: msyazwik@gmail.com | AJ33: https://drive.google.com/file/d/1higsIKBDMSqR5wytlOMo2TtMpXaZx1Zr/view?usp=drivesdk | AK33: https://drive.google.com/file/d/10u2aSY2gBjOdeUhfAj-38IIsIVxUV_Xv/view?usp=drivesdk | AL33: PENOLONG PEGAWAI SENIBINA
A34: 45846.455 | B34: BINAAN LUAR | C34: Walkway/Pedestrian/Footpath | D34: LT04.1 - UPLIGHT TYPE 01 IGUZZINI | E34: {=IFERROR(XLOOKUP(D34, MASTER_KOMPONEN!A:A, MASTER_KOMPONEN!G:G, ""), "")} -> WALKWAY LIGHTING | F34: 322 | G34: E | H34: 14 | I34: 11 | J34: ARAS LANTAI | K34: 00 | L34: ROL P7 - ZON 5 | M34: 05 | N34: 1 | O34: 0007 | P34: 0007 | Q34: E1411.0007-0007 | R34: 1101164MYS.140005.BG0002.TA0112.01.00.05.322 | S34: 101.695 | T34: 3.146992 | U34: https://drive.google.com/uc?export=view&id=1auGH_epA-QvjTbBiHVRTgyh4Vc9Mjr02 | X34: Elyas Mohd Jarami | Y34: elyasdbkl@gmail.com | AA34: TA0112 | AC34: AKTIF | AD34: MUHAMMAD SYAZWI BIN KHUSAIRI | AE34: JURUTERA AWAM, J9 | AF34: https://drive.google.com/file/d/1E6VTZ7moulozcuoRPyeRytD7IVH9Y7zq/view?usp=drivesdk | AG34: https://drive.google.com/file/d/1higsIKBDMSqR5wytlOMo2TtMpXaZx1Zr/view?usp=drivesdk | AH34: msyazwik@gmail.com | AJ34: https://drive.google.com/file/d/1higsIKBDMSqR5wytlOMo2TtMpXaZx1Zr/view?usp=drivesdk | AK34: https://drive.google.com/file/d/15EaAz2XHzJQoUY3xg7jQ9bxMFfKGhGL9/view?usp=drivesdk | AL34: Arkitek
A35: 45846.455 | B35: BINAAN LUAR | C35: Walkway/Pedestrian/Footpath | D35: LT02.2 - PEDESTRIAN LIGHT TYPE 02 IGUZZINI CUSTOM DESIGN (SINGLE SIDE) | E35: {=IFERROR(XLOOKUP(D35, MASTER_KOMPONEN!A:A, MASTER_KOMPONEN!G:G, ""), "")} -> WALKWAY LIGHTING | F35: 311 | G35: E | H35: 14 | I35: 10 | J35: ARAS LANTAI | K35: 00 | L35: ROL P7 - ZON 5 | M35: 05 | N35: 2 | O35: 0003 | P35: 0004 | Q35: E1410.0003-0004 | R35: 1101164MYS.140005.BG0002.TA0112.02.00.05.311 | S35: 101.69515 | T35: 3.146215 | U35: https://drive.google.com/uc?export=view&id=1JzVpja5baXZy88PJT76nSAkZ8eatKQVI | X35: FATIMAH BINTI SHOKARI | Y35: fatimahshokari@gmail.com | AA35: TA0112 | AC35: AKTIF | AD35: MUHAMMAD SYAZWI BIN KHUSAIRI | AE35: JURUTERA AWAM, J9 | AF35: https://drive.google.com/file/d/1WQ-UxposFtrKzeteUeprXRTgHFwqUh8E/view?usp=drivesdk | AG35: https://drive.google.com/file/d/1higsIKBDMSqR5wytlOMo2TtMpXaZx1Zr/view?usp=drivesdk | AH35: msyazwik@gmail.com | AJ35: https://drive.google.com/file/d/1higsIKBDMSqR5wytlOMo2TtMpXaZx1Zr/view?usp=drivesdk | AK35: https://drive.google.com/file/d/1gJ5o6OwyP-zRMmt2x-gb8KoWmsHgZXZi/view?usp=drivesdk | AL35: PENOLONG PEGAWAI SENIBINA JA5
A36: 45846.456 | B36: BINAAN LUAR | C36: Walkway/Pedestrian/Footpath | D36: LT04.1 - UPLIGHT TYPE 01 IGUZZINI | E36: {=IFERROR(XLOOKUP(D36, MASTER_KOMPONEN!A:A, MASTER_KOMPONEN!G:G, ""), "")} -> WALKWAY LIGHTING | F36: 322 | G36: E | H36: 14 | I36: 11 | J36: ARAS LANTAI | K36: 00 | L36: ROL P7 - ZON 5 | M36: 05 | N36: 1 | O36: 0008 | P36: 0008 | Q36: E1411.0008-0008 | R36: 1101164MYS.140005.BG0002.TA0112.01.00.05.322 | S36: 101.69503 | T36: 3.1469038 | U36: https://drive.google.com/uc?export=view&id=1q5QZ4UD5O4twY4kNesrcNkN1H6J2WAkd | Y36: muhamadazmibinyusuf@gmail.com | AA36: TA0112 | AC36: AKTIF | AD36: MUHAMMAD SYAZWI BIN KHUSAIRI | AE36: JURUTERA AWAM, J9 | AG36: https://drive.google.com/file/d/1higsIKBDMSqR5wytlOMo2TtMpXaZx1Zr/view?usp=drivesdk | AH36: msyazwik@gmail.com | AJ36: https://drive.google.com/file/d/1higsIKBDMSqR5wytlOMo2TtMpXaZx1Zr/view?usp=drivesdk | AK36: https://drive.google.com/file/d/1A4fwzYjkGXE06Ar8qAwcPEc-MHe3QGnR/view?usp=drivesdk
A37: 45846.457 | B37: BINAAN LUAR | C37: Landscape | D37: FF02.1– PLANTER SEAT TYPE 01 WITHOUT BACKREST | E37: {=IFERROR(XLOOKUP(D37, MASTER_KOMPONEN!A:A, MASTER_KOMPONEN!G:G, ""), "")} -> BENCHES | F37: 242 | G37: A | H37: 9 | I37: 1 | J37: ARAS LANTAI | K37: 00 | L37: ROL P7 - ZON 5 | M37: 05 | N37: 1 | O37: 0001 | P37: 0001 | Q37: A0901.0001-0001 | R37: 1101164MYS.140005.BG0002.BG0410.01.00.05.242 | S37: 101.69512 | T37: 3.147084804952085, | U37: https://drive.google.com/uc?export=view&id=1-X0TalzEq034swYF_vgEExBTu_W1cVAL | X37: KHAIRUL HAMADI BIN ABDULLAH SANI | Y37: khairulhamadi@gmail.com | AA37: BG0410 | AC37: AKTIF | AD37: MUHAMMAD SYAZWI BIN KHUSAIRI | AE37: JURUTERA AWAM, J9 | AF37: https://drive.google.com/file/d/1TwH8ac0vamZjpCm2V8YFMwD9gEeTvIU_/view?usp=drivesdk | AG37: https://drive.google.com/file/d/1higsIKBDMSqR5wytlOMo2TtMpXaZx1Zr/view?usp=drivesdk | AH37: msyazwik@gmail.com | AJ37: https://drive.google.com/file/d/1higsIKBDMSqR5wytlOMo2TtMpXaZx1Zr/view?usp=drivesdk | AK37: https://drive.google.com/file/d/1pGAJPgWFgQNBMbRtYqwRrTIDYU1cm03G/view?usp=drivesdk | AL37: PENOLONG PEGAWAI SENIBINA
A38: 45846.457 | B38: BINAAN LUAR | C38: Walkway/Pedestrian/Footpath | D38: LT02.2 - PEDESTRIAN LIGHT TYPE 02 IGUZZINI CUSTOM DESIGN (SINGLE SIDE) | E38: {=IFERROR(XLOOKUP(D38, MASTER_KOMPONEN!A:A, MASTER_KOMPONEN!G:G, ""), "")} -> WALKWAY LIGHTING | F38: 311 | G38: E | H38: 14 | I38: 10 | J38: ARAS LANTAI | K38: 00 | L38: ROL P7 - ZON 5 | M38: 05 | N38: 2 | O38: 0005 | P38: 0006 | Q38: E1410.0005-0006 | R38: 1101164MYS.140005.BG0002.TA0112.02.00.05.311 | S38: 101.69515 | T38: 3.146215 | U38: https://drive.google.com/uc?export=view&id=1l-Gj25YhNJStdreobPXJFblwuRyeS9rl | X38: FATIMAH BINTI SHOKARI | Y38: fatimahshokari@gmail.com | AA38: TA0112 | AC38: AKTIF | AD38: MUHAMMAD SYAZWI BIN KHUSAIRI | AE38: JURUTERA AWAM, J9 | AF38: https://drive.google.com/file/d/1WQ-UxposFtrKzeteUeprXRTgHFwqUh8E/view?usp=drivesdk | AG38: https://drive.google.com/file/d/1higsIKBDMSqR5wytlOMo2TtMpXaZx1Zr/view?usp=drivesdk | AH38: msyazwik@gmail.com | AJ38: https://drive.google.com/file/d/1higsIKBDMSqR5wytlOMo2TtMpXaZx1Zr/view?usp=drivesdk | AK38: https://drive.google.com/file/d/1TFgb2JYNd8j68DFttwbheU8PsYyed4TF/view?usp=drivesdk | AL38: PENOLONG PEGAWAI SENIBINA JA5
A39: 45846.457 | B39: BINAAN LUAR | C39: Walkway/Pedestrian/Footpath | D39: LT04.1 - UPLIGHT TYPE 01 IGUZZINI | E39: {=IFERROR(XLOOKUP(D39, MASTER_KOMPONEN!A:A, MASTER_KOMPONEN!G:G, ""), "")} -> WALKWAY LIGHTING | F39: 322 | G39: E | H39: 14 | I39: 11 | J39: ARAS LANTAI | K39: 00 | L39: ROL P7 - ZON 5 | M39: 05 | N39: 1 | O39: 0009 | P39: 0009 | Q39: E1411.0009-0009 | R39: 1101164MYS.140005.BG0002.TA0112.01.00.05.322 | S39: 101.69504 | T39: 3.1469503 | U39: https://drive.google.com/uc?export=view&id=1cKOWZhDJzpX_HCtNzgoPfr36qAELWitV | X39: Elyas Mohd Jarami | Y39: elyasdbkl@gmail.com | AA39: TA0112 | AC39: AKTIF | AD39: MUHAMMAD SYAZWI BIN KHUSAIRI | AE39: JURUTERA AWAM, J9 | AF39: https://drive.google.com/file/d/1E6VTZ7moulozcuoRPyeRytD7IVH9Y7zq/view?usp=drivesdk | AG39: https://drive.google.com/file/d/1higsIKBDMSqR5wytlOMo2TtMpXaZx1Zr/view?usp=drivesdk | AH39: msyazwik@gmail.com | AJ39: https://drive.google.com/file/d/1higsIKBDMSqR5wytlOMo2TtMpXaZx1Zr/view?usp=drivesdk | AK39: https://drive.google.com/file/d/1zgVR_LrcTK_vYA6h_H3nEcM9JU2viUzv/view?usp=drivesdk | AL39: Arkitek
A40: 45846.458 | B40: BINAAN LUAR | C40: Walkway/Pedestrian/Footpath | D40: LT04.1 - UPLIGHT TYPE 01 IGUZZINI | E40: {=IFERROR(XLOOKUP(D40, MASTER_KOMPONEN!A:A, MASTER_KOMPONEN!G:G, ""), "")} -> WALKWAY LIGHTING | F40: 322 | G40: E | H40: 14 | I40: 11 | J40: ARAS LANTAI | K40: 00 | L40: ROL P7 - ZON 5 | M40: 05 | N40: 1 | O40: 0010 | P40: 0010 | Q40: E1411.0010-0010 | R40: 1101164MYS.140005.BG0002.TA0112.01.00.05.322 | S40: 101.69519 | T40: 3.1467943 | U40: https://drive.google.com/uc?export=view&id=11-J-AJhWze4PmoECo4zFIS5Vyk7D6s6L | X40: Elyas Mohd Jarami | Y40: elyasdbkl@gmail.com | AA40: TA0112 | AC40: AKTIF | AD40: MUHAMMAD SYAZWI BIN KHUSAIRI | AE40: JURUTERA AWAM, J9 | AF40: https://drive.google.com/file/d/1E6VTZ7moulozcuoRPyeRytD7IVH9Y7zq/view?usp=drivesdk | AG40: https://drive.google.com/file/d/1higsIKBDMSqR5wytlOMo2TtMpXaZx1Zr/view?usp=drivesdk | AH40: msyazwik@gmail.com | AJ40: https://drive.google.com/file/d/1higsIKBDMSqR5wytlOMo2TtMpXaZx1Zr/view?usp=drivesdk | AK40: https://drive.google.com/file/d/1ORDyFUHYNvmkexPZGgMM1uDIBnfFWy_d/view?usp=drivesdk | AL40: Arkitek
...

Sheet OLD_DATA
A1: Timestamp | B1: Email | C1: ZON ASET | D1: JENIS ASET | E1: KOMPONEN | F1: JENIS ASET | G1: BINAAN LUAR | H1: ARAS | I1: RUANG | J1: ID KOMPONEN | K1: Bidang Kejuruteraan | L1: Sistem | M1: Subsistem | N1: STATUS | O1: BILANGAN KOMPONEN | P1: UNIT | Q1: GAMBAR 1 | R1: KOORDINAT | S1: KOORDINAT X | T1: KOORDINAT Y
A2: 45785.441 | B2: azuansalwa5960@gmail.com | C2: P7 - ZON 1 | D2: BINAAN LUAR | E2: FF01.7– BENCH TYPE 07B FLOW BENCH | F2: BINAAN LUAR | G2: BG0410 | H2: 0 | I2: 1 | J2: 208 | K2: A | L2: 9 | M2: 1 | N2: AKTIF | O2: 2 | P2: UNIT/BUAH/NOS/SETS | Q2: https://drive.google.com/uc?export=view&id=14gxy8pHBhmnfjvLVikep0M0M__Fu_dRz | R2: 3°09'02.7"N 101°41'36.9"E | S2: 101°41'36.9"E | T2: 3°09'02.7"N
A3: 45785.443 | B3: azuansalwa5960@gmail.com | C3: P7 - ZON 1 | D3: BINAAN LUAR | E3: FF01.7 – BENCH TYPE 07A FLOW BENCH | F3: BINAAN LUAR | G3: BG0410 | H3: 0 | I3: 1 | J3: 207 | K3: A | L3: 9 | M3: 1 | N3: AKTIF | O3: 2 | P3: UNIT/BUAH/NOS/SETS | Q3: https://drive.google.com/uc?export=view&id=1LEajXLHX5yoE7G-74zHCksL5uDiYuMMm | R3: 3°09'02.7"N 101°41'36.9"E | S3: 101°41'36.9"E | T3: 3°09'02.7"N
A4: 45785.448 | B4: azuansalwa5960@gmail.com | C4: P7 - ZON 1 | D4: BINAAN LUAR | E4: SG05A – IDENTIFICATION MOUNTED SIGNAGE | F4: BINAAN LUAR | G4: BG0410 | H4: 0 | I4: 1 | J4: 284 | K4: A | L4: 8 | M4: 7 | N4: AKTIF | O4: 1 | P4: UNIT/BUAH/NOS/SETS | Q4: https://drive.google.com/uc?export=view&id=1sj9U0sNXGpBIiHnT4p5PPnoayMtcNQ4u | R4: 3°09'02.7"N 101°41'36.9"E | S4: 101°41'36.9"E | T4: 3°09'02.7"N
A5: 45816.438 | B5: khairulhamadi@gmail.com | C5: P7 - ZON 5 | D5: BINAAN LUAR | E5: FF03.2 – BIN TYPE 02 | F5: BINAAN LUAR | G5: BG0410 | H5: 0 | I5: 5 | J5: 246 | K5: A | L5: 9 | M5: 1 | N5: AKTIF | O5: 1 | P5: UNIT/BUAH/NOS/SETS | Q5: https://drive.google.com/uc?export=view&id=1e51aDsCbDPxMnijF5y8YfLlIb-goJKG5 | R5: 3.1472616 101.6944587 | S5: 101.69446 | T5: 3.1472616
A6: 45816.438 | B6: khairulhamadi@gmail.com | C6: P7 - ZON 5 | D6: BINAAN LUAR | E6: FF03.2 – BIN TYPE 02 | F6: BINAAN LUAR | G6: BG0410 | H6: 0 | I6: 5 | J6: 246 | K6: A | L6: 9 | M6: 1 | N6: AKTIF | O6: 1 | P6: UNIT/BUAH/NOS/SETS | Q6: https://drive.google.com/uc?export=view&id=1fT6RNzOqyVnAcaPCw7lCQpcuTQCh8yrz | R6: 3.1472616 101.6944587 | S6: 101.69446 | T6: 3.1472616
A7: 45816.448 | B7: yaziddbkl@gmail.com | C7: P7 - ZON 4 | D7: BINAAN LUAR | E7: SG01A – PRIMARY GATEWAY SINAGE | F7: BINAAN LUAR | G7: TA0112 | H7: 0 | I7: 4 | J7: 275 | K7: A | L7: 8 | M7: 7 | N7: AKTIF | O7: 1 | P7: UNIT/BUAH/NOS/SETS | Q7: https://drive.google.com/uc?export=view&id=15DwG6yS7XuN2NMRC8Rvpo0ydR63FqrCz | R7: 3.149628756494498 101.6946152332847 | S7: 101.69462 | T7: 3.1496288
A8: 45816.448 | B8: khairulhamadi@gmail.com | C8: P7 - ZON 5 | D8: BINAAN LUAR | E8: LT01.15 - STREET LIGHT TYPE 15 SCHREDER HESTIA LED WITH ATTACHED ELEMENTS (SINGLE LAMP) | F8: BINAAN LUAR | G8: TA0112 | H8: 0 | I8: 5 | J8: 305 | K8: E | L8: 14 | M8: 11 | N8: AKTIF | O8: 1 | P8: UNIT/BUAH/NOS/SETS | Q8: https://drive.google.com/uc?export=view&id=1lOgyIQpATRIxFxAZQu9_k5Z3Q0MpuS70 | R8: 3.1469195 101.6945814 | S8: 101.69458 | T8: 3.1469195
A9: 45816.45 | B9: khairulhamadi@gmail.com | C9: P7 - ZON 5 | D9: BINAAN LUAR | E9: LT01.15 - STREET LIGHT TYPE 15 SCHREDER HESTIA LED WITH ATTACHED ELEMENTS (SINGLE LAMP) | F9: BINAAN LUAR | G9: TA0112 | H9: 0 | I9: 5 | J9: 305 | K9: E | L9: 14 | M9: 11 | N9: AKTIF | O9: 1 | P9: UNIT/BUAH/NOS/SETS | Q9: https://drive.google.com/uc?export=view&id=17HYEvsjD1a25pH_0Qqu4n9ztSHY_gm3Z | R9: 3.1470493 101.6946043 | S9: 101.6946 | T9: 3.1470493
A10: 45816.453 | B10: yaziddbkl@gmail.com | C10: P7 - ZON 4 | D10: BINAAN LUAR | E10: LT04.1 - UPLIGHT TYPE 01 IGUZZINI | F10: BINAAN LUAR | G10: BG0410 | H10: 0 | I10: 4 | J10: 322 | K10: E | L10: 14 | M10: 11 | N10: AKTIF | O10: 14 | P10: UNIT/BUAH/NOS/SETS | Q10: https://drive.google.com/uc?export=view&id=1MtPlfm7Eg74usU2-E1Z_5VJHKQY6w-Sh | R10: 3.1495551071644683, 101.69457097683815 | S10: 101.69457 | T10: 3.1495551071644683,
A11: 45816.455 | B11: yaziddbkl@gmail.com | C11: P7 - ZON 4 | D11: BINAAN LUAR | E11: FF01.11– BENCH TYPE 11A ESCOFET SOCRATES | F11: BINAAN LUAR | G11: BG0410 | H11: 0 | I11: 4 | J11: 214 | K11: A | L11: 9 | M11: 1 | N11: AKTIF | O11: 2 | P11: UNIT/BUAH/NOS/SETS | Q11: https://drive.google.com/uc?export=view&id=14LdGh2pWa1ybzEA59FK128FdkvQO5hsS | R11: 3.1495551071644683, 101.69457097683815 | S11: 101.69457 | T11: 3.1495551071644683,
A12: 45816.457 | B12: yaziddbkl@gmail.com | C12: P7 - ZON 4 | D12: BINAAN LUAR | E12: LT04.3 - UPLIGHT TYPE 03 IGUZZINI | F12: BINAAN LUAR | G12: BG0410 | H12: 0 | I12: 4 | J12: 324 | K12: E | L12: 14 | M12: 11 | N12: AKTIF | O12: 4 | P12: UNIT/BUAH/NOS/SETS | Q12: https://drive.google.com/uc?export=view&id=1TdR9s9JnZ-GDywNzF8UGkfBq1C8ccWtY | R12: 3.1496234001797614, 101.6945629302115 | S12: 101.69456 | T12: 3.1496234001797614,
A13: 45816.459 | B13: yaziddbkl@gmail.com | C13: P7 - ZON 4 | D13: BINAAN LUAR | E13: FF09.4 – TREE GRATE TYPE 04 | F13: BINAAN LUAR | G13: BG0410 | H13: 0 | I13: 4 | J13: 258 | K13: A | L13: 9 | M13: 1 | N13: AKTIF | O13: 6 | P13: UNIT/BUAH/NOS/SETS | Q13: https://drive.google.com/uc?export=view&id=1ADQV6pP-ac5MKXyOHyGwvkpJyuDBC83f | R13: 3.14953368190383, 101.69465412531346 | S13: 101.69465 | T13: 3.14953368190383,
A14: 45816.462 | B14: yaziddbkl@gmail.com | C14: P7 - ZON 4 | D14: BINAAN LUAR | E14: FF02.1– PLANTER SEAT TYPE 01 WITHOUT BACKREST | F14: BINAAN LUAR | G14: BG0410 | H14: 0 | I14: 4 | J14: 242 | K14: A | L14: 9 | M14: 1 | N14: AKTIF | O14: 1 | P14: UNIT/BUAH/NOS/SETS | Q14: https://drive.google.com/uc?export=view&id=1b2esYBKHVyGNV67RZF4-oiIsxCiXDD7m | R14: 3.1496689288541435, 101.69459377561364 | S14: 101.69459 | T14: 3.1496689288541435,
A15: 45816.463 | B15: azuansalwa5960@gmail.com | C15: P7 - ZON 1 | D15: BINAAN LUAR | E15: FF02.1– PLANTER SEAT TYPE 01 WITHOUT BACKREST | F15: BINAAN LUAR | G15: BG0410 | H15: 0 | I15: 1 | J15: 242 | K15: A | L15: 9 | M15: 1 | N15: AKTIF | O15: 3 | P15: UNIT/BUAH/NOS/SETS | Q15: https://drive.google.com/uc?export=view&id=11qkBErlu3t9JqhpbxjPqMhljP8XbsSZt | R15: 3°09'02.7"N 101°41'36.9"E | S15: 101°41'36.9"E | T15: 3°09'02.7"N
A16: 45816.465 | B16: azuansalwa5960@gmail.com | C16: P7 - ZON 1 | D16: BINAAN LUAR | E16: FF01.11– BENCH TYPE 11A ESCOFET SOCRATES | F16: BINAAN LUAR | G16: BG0410 | H16: 0 | I16: 1 | J16: 214 | K16: A | L16: 9 | M16: 1 | N16: AKTIF | O16: 7 | P16: UNIT/BUAH/NOS/SETS | Q16: https://drive.google.com/uc?export=view&id=1c8Z-6PIjUvKCfVb1LLe4nuAJrBsomRZk | R16: 3°09'02.7"N 101°41'36.9"E | S16: 101°41'36.9"E | T16: 3°09'02.7"N
A17: 45816.467 | B17: yaziddbkl@gmail.com | C17: P7 - ZON 4 | D17: BINAAN LUAR | E17: RAILING TYPE 10 , 11 & 12 RIVERFRONT ALONG HERITAGE AREA | F17: BINAAN LUAR | G17: TA0112 | H17: 0 | I17: 4 | J17: 194 | K17: A | L17: 9 | M17: 1 | N17: AKTIF | O17: 1 | P17: UNIT/BUAH/NOS/SETS | Q17: https://drive.google.com/uc?export=view&id=1Y21CT-CdqGjnvisAXqu-vGcCP2C_RBbo | R17: 3.149552052544829, 101.69473550646923 | S17: 101.69474 | T17: 3.149552052544829,
A18: 45816.468 | B18: azuansalwa5960@gmail.com | C18: P7 - ZON 1 | D18: BINAAN LUAR | E18: FF03.2 – BIN TYPE 02 | F18: BINAAN LUAR | G18: BG0410 | H18: 0 | I18: 1 | J18: 246 | K18: A | L18: 9 | M18: 1 | N18: AKTIF | O18: 3 | P18: UNIT/BUAH/NOS/SETS | Q18: https://drive.google.com/uc?export=view&id=1z5jke2Dy4rYjOmx35P9xoDTtrvF4oAGC | R18: 3°09'03.5"N 101°41'39.1"E | S18: 101°41'39.1"E | T18: 3°09'03.5"N
A19: 45816.7 | B19: yaziddbkl@gmail.com | C19: P7 - ZON 4 | D19: BINAAN LUAR | E19: SG01A – PRIMARY GATEWAY SINAGE | F19: BINAAN LUAR | G19: TA0112 | H19: 0 | I19: 4 | J19: 275 | K19: A | L19: 8 | M19: 7 | N19: AKTIF | O19: 1 | P19: UNIT/BUAH/NOS/SETS | Q19: https://drive.google.com/uc?export=view&id=1HI8IkqHatdttbEYWbEMEU-T15LyhadMb | R19: 3.1494921704601193, 101.69471045169996 | S19: 101.69471 | T19: 3.1494921704601193,
A20: 45846.429 | B20: fatimahshokari@gmail.com | C20: P7 - ZON 5 | D20: BINAAN LUAR | E20: SG03B – PEDESTRIAN DIRECTIONAL TOTEM | F20: BINAAN LUAR | G20: TA0112 | H20: 0 | I20: 5 | J20: 278 | K20: A | L20: 8 | M20: 7 | N20: AKTIF | O20: 1 | P20: UNIT/BUAH/NOS/SETS | Q20: https://drive.google.com/uc?export=view&id=1HltMRknLc5wf8RQ3Hm5S4FEQBoFepq3v | R20: 3.1471577 101.6941637 | S20: 101.69416 | T20: 3.1471577
A21: 45846.433 | B21: fatimahshokari@gmail.com | C21: P7 - ZON 5 | D21: BINAAN LUAR | E21: LT01.15 - STREET LIGHT TYPE 15 SCHREDER HESTIA LED WITH ATTACHED ELEMENTS (SINGLE LAMP) | F21: BINAAN LUAR | G21: TA0112 | H21: 0 | I21: 5 | J21: 305 | K21: E | L21: 14 | M21: 11 | N21: AKTIF | O21: 1 | P21: UNIT/BUAH/NOS/SETS | Q21: https://drive.google.com/uc?export=view&id=1MEmEsyzrlwamdM9VUsl08djww5cdDjI6 | R21: 3.1470254 101.6949628 | S21: 101.69496 | T21: 3.1470254
